Workbook

Sheet Page_de_garde
C31: FORMULAIRE DE DECLARATION PRUDENTIELLE DES ETABLISSEMENTS DE CREDIT ET DES COMPAGNIES FINANCIERES (FODEP)

Sheet ADPE
A1: ATTESTATION DE DECLARATION PRUDENTIELLE
A5: ETAT : | N5: ETABLISSEMENT :
D7: A | E7: A | F7: A | G7: A | H7: M | I7: M | K7: J | L7: J
E9: Date d'arrêté | O9: C | P9: I | Q9: B | T9: LC
A12: Personne-responsable du renseignement du FODEP :
D16: Prénoms et Nom :
D18: Fonction :
D20: Téléphone : | Y20: Poste :
D22: E-mail :
A24: Personne-responsable de la transmission du FODEP à la plateforme de reporting BCEAO
D26: Prénoms et Nom :
D28: Fonction :
D30: Téléphone : | Y30: Poste :
D32: E-mail :
A34: CERTIFICATION
A37: Nous, | S37: et
A39: certifions que le présent formulaire a été rempli conformément aux exigences du dispositif prudentiel applicable aux établissements de crédit et aux compagnies financières de l'Union Monétaire Ouest Africaine.
A40: En outre, nous attestons qu'au meilleur de notre connaissance, les données contenues dans le présent formulaire sont fiables, intègres et exhaustives.
A43: Code Signature :
B45: Fonction : | U45: Date :
X46: (AAAA-MM-JJ)
A49: Code Signature :
B51: Fonction : | U51: Date :
X52: (AAAA-MM-JJ)

Sheet Liste_EP_à_renseigner
A1: LISTE DES ETATS PRUDENTIELS A RENSEIGNER
A8: N° Etat prudentiel | B8: Intitulé | C8: Sur une Base
C9: Individuelle | D9: Sous-consolidée | E9: Consolidée
A10: EP01 | B10: Etat de conformité aux normes prudentielles | C10: 68 | D10: 68 | E10: 68
A11: EP02 | B11: Calcul des ratios de solvabilité | C11: 68 | D11: 68 | E11: 68
A12: EP03 | B12: Calcul des fonds propres sur base individuelle | C12: 68 | D12: 32 | E12: 32
A13: EP04 | B13: Dispositions transitoires sur base individuelle : Retrait progressif des éléments de fonds propres non admissibles | C13: 68 | D13: 32 | E13: 32
A14: EP05 | B14: Calcul des fonds propres sur base consolidée | C14: 32 | D14: 68 | E14: 68
A15: EP06 | B15: Dispositions transitoires sur base consolidée : Retrait progressif des éléments de fonds propres non admissibles | C15: 32 | D15: 68 | E15: 68
A16: EP07 | B16: Fonds propres admissibles émis par des filiales | C16: 32 | D16: 68 | E16: 68
A17: EP08 | B17: Total des actifs pondérés des risques | C17: 68 | D17: 68 | E17: 68
A18: EP09 | B18: Ventilation du bilan entre les différentes catégories d'expositions | C18: 68 | D18: 68 | E18: 68
A19: EP10 | B19: Ventilation des engagements totaux hors-bilan entre les différentes catégories d'expositions | C19: 68 | D19: 68 | E19: 68
A20: EP11 | B20: Expositions au risque de contrepartie | C20: 68 | D20: 68 | E20: 68
A21: EP12 | B21: Risque de crédit : expositions sur les souverains | C21: 68 | D21: 68 | E21: 68
... A48: EP39 | B48: Liste des principaux actionnaires, dirigeants, membres du personnel et parties liées bénéficiant de prêts significatifs | C48: 68 | D48: 68 | E48: 68

Sheet EP01
A1: ETAT DE CONFORMITE AUX NORMES PRUDENTIELLES | H1: EP01
A8: Code DISPRU | B8: Liste des normes prudentielles | E8: Référence | F8: Niveau à respecter | G8: Niveau observé | H8: Situation de l'établissement
B9: A. Normes de solvabilité
A10: RA001 | B10: Ratio de fonds propres CET 1 (%) | E10: EP02 | F10: 0.075 | G10: ='EP02'!F10 | H10: =IF($G10>($F10),"CONFORME","INFRACTION")
A11: RA002 | B11: Ratio de fonds propres de base T1 (%) | E11: EP02 | F11: 0.085 | G11: ='EP02'!F11 | H11: =IF($G11>($F11),"CONFORME","INFRACTION")
A12: RA003 | B12: Ratio de solvabilité total (%) | E12: EP02 | F12: 0.115 | G12: ='EP02'!F12 | H12: =IF($G12>($F12),"CONFORME","INFRACTION")
B13: B. Norme de division des risques
A14: RA004 | B14: Norme de division des risques | E14: EP29 | F14: 0.25 | G14: ='EP29'!F72 | H14: =IF($G14>($F14),"INFRACTION","CONFORME")
B15: C. Ratio de levier
A16: RA005 | B16: Ratio de levier | E16: EP33 | F16: 0.03 | G16: ='EP33'!C35 | H16: =IF($G16>($F16),"CONFORME","INFRACTION")
B17: D. Autres normes prudentielles
A18: RA006 | B18: Limite individuelle sur les participations dans les entités commerciales ( 25% capital de l'entreprise) | E18: EP35 | F18: 0.25 | G18: ='EP35'!G13 | H18: =IF($G18>($F18),"INFRACTION","CONFORME")
A19: RA007 | B19: Limite individuelle sur les participations dans les entités commerciales (15% des fonds propres T1 de l'établissement) | E19: EP35 | F19: 0.15 | G19: ='EP35'!H13 | H19: =IF($G19>($F19),"INFRACTION","CONFORME")
A20: RA008 | B20: Limite globale de participations dans les entités commerciales (60% des fonds propres effectifs de l'établissement) | E20: EP35 | F20: 0.6 | G20: ='EP35'!I32 | H20: =IF($G20>($F20),"INFRACTION","CONFORME")
A21: RA009 | B21: Limite sur les immobilisations hors exploitation | E21: EP36 | F21: 0.15 | G21: ='EP36'!E17 | H21: =IF($G21>($F21),"INFRACTION","CONFORME")
A22: RA010 | B22: Limite sur le total des immobilisations et des participations | E22: EP37 | F22: 1 | G22: ='EP37'!E16 | H22: =IF($G22>($F22),"INFRACTION","CONFORME")
A23: RA011 | B23: Limite sur les prêts aux actionnaires , aux dirigeants et au personnel | E23: EP38 | F23: 0.2 | G23: ='EP38'!L14 | H23: =IF($G23>($F23),"INFRACTION","CONFORME")

Sheet EP02
A1: CALCUL DES RATIOS DE SOLVABILITE | G1: EP02
A8: Code DISPRU | B8: Poste | E8: Référence | F8: Niveau /Montant estimé
B9: A. Normes de solvabilité
A10: RA001 | B10: Ratio de fonds propres CET 1 (%) | E10: a x 100 / d | F10: =F14/F18
A11: RA002 | B11: Ratio de fonds propres de base T1 (%) | E11: b x 100 / d | F11: =F15/F18
A12: RA003 | B12: Ratio de solvabilité total (%) | E12: cx 100 / d | F12: =F16/F18
B13: B. Fonds propres
A14: FPI22 / FPC22 | B14: Fonds propres de base durs (CET 1) | E14: EP03 / EP05 | G14: (a)
A15: FPI29 / FPC29 | B15: Fonds propres de base (T1) | E15: EP03 / EP05 | G15: (b)
A16: FPI41 / FPC41 | B16: Fonds propres effectifs (FPE) | E16: EP03 / EP05 | G16: (c)
B17: C. Actifs pondérés des risques (APR)
A18: APR04 | B18: Actifs pondérés des risques de crédit, de marché et opérationel | E18: EP08 | F18: ='EP08'!E34 | G18: (d)

Sheet EP03
A1: CALCUL DES FONDS PROPRES SUR BASE INDIVIDUELLE | C1: EP03
A9: Code DISPRU | B9: Poste | C9: Montant
B10: A. Fonds propres de base durs (CET 1)
A11: FPI01 | B11: Capital social libéré
A12: FPI02 | B12: Primes liées à l'émission des instruments CET1 | C12: 0
A13: FPI03 | B13: Réserve spéciale
A14: FPI04 | B14: Autres réserves | C14: 0
A15: FPI05 | B15: Report à nouveau créditeur
A16: FPI06 | B16: Résultat bénéficiaire
A17: FPI07 | B17: Eléments de CET1 non admissibles au 1er janvier 2018 et inclus dans le CET1 selon les dispositions transitoires | C17: 0
A18: FPI08 | B18: Total des fonds propres CET1 avant déductions applicables | C18: =C11+C12+C13+C14+C15+C16+C17
A19: FPI09 | B19: (-) Report à nouveau débiteur | C19: 0
A20: FPI10 | B20: (-) Résultat déficitaire | C20: 0
A21: IM012 | B21: (-) Immobilisations incorporelles (nettes d'impôts différés passif)
A22: ID009 | B22: (-) Impôt différé actif dépendant de la rentabilité future de l’établissement et ne résultant pas de différences temporaires (net d'impôts différés passif) | C22: 0
A23: PA156 | B23: (-) Participations croisées éligibles au CET1 dans les établissements, les entreprises d'assurance et les autres entités financières | C23: 0
A24: PA173 | B24: (-) Participations significatives éligibles au CET1 et qui ne sont pas des actions ordinaires | C24: 0
A25: FPI11 | B25: (-) Réserves de valorisation pour positions moins liquides | C25: 0
A26: PA149 | B26: (-) Excédent de la limite de participations dans des entités commerciales | C26: 0
A27: IM006 | B27: (-) Excédent de la limite applicable aux immobilisations hors exploitation | C27: 0
A28: IM010 | B28: (-) Excédent de la limite applicable au total des immobilisations et participations | C28: 0
A29: PR004 | B29: (-) Excédent de la limite applicable aux prêts aux actionnaires, aux dirigeants et au personnel | C29: 0
A30: FPI12 | B30: (-) Expositions sur les établissements qui disposent de fonds propres négatifs | C30: 0
A31: FPI13 | B31: (-) Ajustements réglementaires à appliquer au CET1 en raison de l'insuffisance des fonds propres de base additionnels (AT1) pour couvrir les déductions | C31: 0
A32: FPI14 | B32: Total des fonds propres CET1 ajustés avant déductions liées à des seuils | C32: =C18+C21
A33: PA163 | B33: (-) Participations non significatives éligibles au CET1 dans les établissements, les entreprises d'assurance et les autres entités financières | C33: 0
A34: FPI15 | B34: Total des fonds propres CET1 ajustés des déductions liées aux participations non significatives | C34: =C32
A35: PA172 | B35: (-) Participations significatives éligibles au CET1 dans les établissements, les entreprises d'assurance et les autres entités financières | C35: 0
A36: ID011 | B36: (-) Impôts différés actifs résultant de différences temporaires (nets de passifs d'impôt associés) | C36: 0
A37: FPI16 | B37: Total des fonds propres CET1 ajustés des déductions individuelles liées aux participations significatives et aux impôts différés actifs résultant de différences temporaires | C37: =C34
A38: FPI20 | B38: (-) Montant dépassant le seuil de 15% du CET1 | C38: 0
A39: FPI21 | B39: (-) Autres déductions applicables au CET1 | C39: 0
A40: FPI22 | B40: TOTAL DES FONDS PROPRES CET1 | C40: =C37
B41: B. Fonds propres de base additionnels (AT1)
A42: FPI23 | B42: Instruments de capital libérés | C42: 0
A43: FPI24 | B43: Primes liées à l'émission des instruments AT1 | C43: 0
A44: FPI25 | B44: Instruments de CET1 non admissibles au 1er janvier 2018 et éligibles dans les fonds propres fonds propres de base additionnels (AT1) | C44: 0
A45: FPI26 | B45: Total des fonds propres AT1 avant déductions applicables | C45: 0
A46: PA157 | B46: (-) Participations croisées éligibles au AT1 dans les établissements, les entreprises d'assurance et les autres entités financières | C46: 0
A47: PA164 | B47: (-) Participations non significatives éligibles au AT1 dans les établissements, les entreprises d'assurance et les autres entités financières | C47: 0
...

Sheet EP3M
A1: CALCUL DES FONDS PROPRES SUR BASE INDIVIDUELLE | D1: EP03
A9: Poste mémoire - Déductions applicables aux fonds propres sur base individuelle
A11: Code DISPRU | B11: Poste | C11: Montant | D11: Formules de calcul
B12: A. Immobilisations incorporelles
A13: IM011 | B13: Immobilisations incorporelles | D13: (a)
A14: ID001 | B14: (-) Impôts différés passif associés | C14: 0 | D14: (b)
A15: IM012 | B15: Immobilisations incorporelles (nettes d'impôts différés passif) | D15: (c)=a+b
B16: B. Impôts différés actifs
B17: B.1. Impôt différé actif ne dépendant pas de la rentabilité future de l’établissement
A18: ID003 | B18: Total impôt différé actif qui ne dépend pas de la rentabilité future de l'établissement (montant brut) | C18: 0 | D18: (a)
A19: ID004 | B19: (-) Impôts différés passif associés | C19: 0 | D19: (b)
A20: ID005 | B20: Total impôt différé actif qui ne dépend pas de la rentabilité future de l'établissement (net des impôts différés passif associés) | C20: 0 | D20: (c)=a+b
B21: B.2. Impôt différé actif dépendant de la rentabilité future de l’établissement
A22: ID006 | B22: Total impôt différé actif qui dépend de la rentabilité future de l'établissement (montant brut) | C22: 0 | D22: (a)
A23: ID007 | B23: (-) Impôts différés passif associés | C23: 0 | D23: (b)
A24: ID008 | B24: Total impôt différé actif qui dépend de la rentabilité future de l'établissement (net des impôts différés passif associés); dont | C24: 0 | D24: (c)=a+b
A25: ID009 | B25: ne résultant pas de différences temporaires (net au prorata de l'impôt différé passif) | C25: 0
A26: ID010 | B26: résultant de différences temporaires (net au prorata de l'impôt différé passif) | C26: 0
B27: C. Participations
B28: C.1. Détail des participations dans les établissements, les entreprises d'assurance et les autres entités financières
A29: PA150 | B29: Total des participations dans les établissements | C29: 0 | D29: (a)
A30: PA151 | B30: Total des participations dans les entreprises d'assurance et les autres entités financières | C30: 0 | D30: (b)
A31: PA152 | B31: Total des participations dans les établissements, les entreprises d'assurance et les autres entités financières ; dont | C31: 0 | D31: (c)=a+b
A32: PA153 | B32: Participations croisées | C32: 0
A33: PA154 | B33: Participations non significatives (détention de part ≤ 10% ) | C33: 0 | D33: (d)
A34: PA155 | B34: Participations significatives (détention de part > 10% ) | C34: 0 | D34: (e)
B35: C.2. Participations croisées
A36: PA156 | B36: Eligibles au CET1 | C36: 0
A37: PA157 | B37: Eligibles au AT1 | C37: 0
A38: PA158 | B38: Eligibles au T2 | C38: 0
B39: C.3. Participations non significatives
A40: PA159 | B40: Eligibles au CET1 | C40: 0 | D40: (f)
A41: PA160 | B41: Eligibles au AT1 | C41: 0 | D41: (g)
A42: PA161 | B42: Eligibles au T2 | C42: 0 | D42: (h)
A43: FPI14 | B43: Total des fonds propres CET1 ajustés avant déductions liées à des seuils | C43: =+'EP03'!C69 | D43: (i)
A44: PA162 | B44: Participations non significatives à déduire des fonds propres ; dont | C44: 0 | D44: (j)=max[0; (d-0,1*i)]
A45: PA163 | B45: (-) Déduction affectée au CET1 | C45: 0 | D45: (k)=j*(f/d)
A46: PA164 | B46: (-) Déduction affectée au AT1 | C46: 0 | D46: (l)=j*(g/d)
A47: PA165 | B47: (-) Déduction affectée au T2 | C47: 0 | D47: (m)=j*(h/d)
A48: PA166 | B48: Participations non significatives non déduites des fonds propres | C48: 0 | D48: (n)=d-j
...

Sheet EP04
A1: DISPOSITIONS TRANSITOIRES SUR BASE INDIVIDUELLE : RECLASSEMENT ET RETRAIT PROGRESSIF DES ELEMENTS DE FONDS PROPRES NON ADMISSIBLES | D1: EP04
A9: Code DISPRU | B9: Poste | C9: Montant | D9: Formules de calcul
A10: DT001 | B10: Taux de retrait des éléments de fonds propres non admissibles comptabilisés dans les fonds propres pendant la période de transition | C10: 0.9 | D10: (a)
B12: A. Retrait progressif des instruments de fonds propres de base durs (CET1) non admissibles
A13: FPI01 | B13: Capital social libéré dont ; | D13: (b)
A14: DT002 | B14: Part du capital social non admissibles comme éléments de CET1 au 1er janvier 2018 et les primes d'émission y relatives | D14: (c)
A15: DT003 | B15: Provisions réglementées | D15: (d)
A16: DT004 | B16: Fonds affectés | C16: 0 | D16: (e)
A17: DT005 | B17: Total des éléments de CET1 non admissibles au 1er janvier 2018 | C17: 0 | D17: (f)=c+d+e
A18: DT006 | B18: Montant maximal des éléments de CET1 non admissibles qui peut être inclus dans les fonds propres | C18: 0 | D18: (g)=fxa
A19: DT007 | B19: Montant réel des éléments de CET1 non admissibles en circulation à la date de déclaration | D19: (h)
A20: FPI07 | B20: Eléments de CET1 non admissibles au 1er janvier 2018 et inclus dans le CET1 selon les dispositions transitoires | C20: 0 | D20: i=min(g,h)
A21: FPI25 | B21: Instruments de CET1 non admissibles au 1er janvier 2018 et éligibles dans les fonds propres de base additionnels (AT1)
A22: DT008 | B22: Eléments de CET1 non admissibles au 1er janvier 2018 et éligibles dans les fonds propres complémentaires (T2) dont ; | C22: 0
A23: FPI33 | B23: Autres instruments de CET1 non admissibles au 1er janvier 2018 et éligibles dans les fonds propres complémentaires (T2)
A24: FPI35 | B24: Provisions réglementées | C24: 0
A25: FPI36 | B25: Fonds affectés | C25: 0
A26: DT009 | B26: Eléments de CET1 non admissibles au 1er janvier 2018 et exclus des fonds propres.
B28: B. Retrait progressif des éléments de fonds propres complémentaires (T2) non admissibles
A29: DT010 | B29: Dettes subordonnées en circulation au 1er janvier 2018* dont ; | D29: (j)
A30: DT011 | B30: Part des dettes subordonnées en circulation au 1er janvier 2018* non admissibles comme élément de fonds propres complémentaires (T2) | C30: 0 | D30: (k)
A31: DT012 | B31: Ecarts de réévaluation | D31: (l)
A32: DT013 | B32: Autres éléments de fonds propres complémentaires (T2) non admissibles au 1er janvier 2018 | D32: (m)
A33: DT014 | B33: Total des éléments de fonds propres complémentaires (T2) non admissibles au 1er janvier 2018 | C33: 0 | D33: (n)=k+l+m
A34: DT015 | B34: Montant maximal éléments de fonds propres complémentaires (T2) non admissibles qui peut être inclus dans les fonds propres | C34: 0 | D34: (o)=nxa
A35: DT016 | B35: Montant réel des éléments de fonds propres complémentaires (T2) non admissibles en circulation à la date de déclaration** | D35: (p)
A36: FPI34 | B36: Eléments de fonds propres complémentaires (T2) non admissibles au 1er janvier 2018 et inclus dans les fonds propres | C36: 0 | D36: (q)=min(o,p)
A38: * après amortissement, s'il y a lieu, jusqu'au 1er janvier 2018
A39: ** après amortissement, s'il y a lieu, jusqu'à la date de déclaration

Sheet EP05
A1: CALCUL DES FONDS PROPRES SUR BASE CONSOLIDEE | C1: EP05
A9: Code DISPRU | B9: Poste | C9: Montant
B10: A. Fonds propres de base durs (CET 1)
A11: FPC01 | B11: Capital social libéré
A12: FPC02 | B12: Primes liées à l'émission des instruments CET1
A13: FPC03 | B13: Réserve spéciale
A14: FPC04 | B14: Autres réserves
A15: FPC05 | B15: Report à nouveau créditeur
A16: FPC06 | B16: Résultat bénéficiaire
A17: FPC07 | B17: Eléments de CET1 non admissibles au 1er janvier 2018 et inclus dans le CET1 selon les dispositions transitoires
A18: INT16 | B18: Intérêts minoritaires à inclure dans le CET1
A19: FPC08 | B19: Total des fonds propres CET1 avant déductions applicables
A20: FPC09 | B20: (-) Report à nouveau débiteur
A21: FPC10 | B21: (-) Résultat déficitaire
A22: IM014 | B22: (-) Goodwill (net d'impôts différés passif)
... A42: FPC22 | B42: TOTAL DES FONDS PROPRES CET1
B43: B. Fonds propres de base additionnels (AT1)
A44: FPC23 | B44: Instruments de capital libérés
A45: FPC24 | B45: Primes liées à l'émission des instruments AT1
A46: FPC25 | B46: Instruments de CET1 non admissibles au 1er janvier 2018 et éligibles dans les fonds propres fonds de base additionnels (AT1)
A47: INT22 | B47: Intérêts minoritaires à inclure dans l'AT1
A48: FPC26 | B48: Total des fonds propres AT1 avant déductions applicables
A49: PA157 | B49: (-) Participations croisées éligibles au AT1 dans les établissements, les entreprises d'assurance et les autres entités financières
A50: PA164 | B50: (-) Participations non significatives éligibles au AT1 dans les établissements, les entreprises d'assurance et les autres entités financières
A51: PA174 | B51: (-) Participations significatives éligibles au AT1 dans les établissements, les entreprises d'assurance et les autres entités financières
A52: FPC27 | B52: (-) Ajustements réglementaires à appliquer au fonds propres AT1 en raison de l'insuffisance des fonds propres complémentaires (T2) pour couvrir les déductions
A53: FPC28 | B53: Total des fonds propres AT1
B54: C. Fonds Propres de Base (T1)
A55: FPC29 | B55: TOTAL DES FONDS PROPRES DE BASE T1
B56: D. Fonds Propres Complémentaires (T2)
A57: FPC30 | B57: Emprunts subordonnés
A58: FPC31 | B58: Autres instruments de capital libérés
A59: FPC32 | B59: Primes liées à l'émission des instruments T2
A60: FPC33 | B60: Autres instruments de CET1 non admissibles au 1er janvier 2018 et éligibles dans les fonds propres complémentaires (T2)
A61: FPC34 | B61: Eléments de fonds propres complémentaires (T2) non admissibles au 1er janvier 2018 et inclus dans les fonds propres
A62: FPC35 | B62: Provisions réglementées
A63: FPC36 | B63: Fonds affectés
A64: FPC37 | B64: Subventions d’investissement
A65: FPC38 | B65: Comptes bloqués d'actionnaires ou d'associés
A66: INT28 | B66: Intérêts minoritaires à inclure dans le T2
...

Sheet EP5M
A1: CALCUL DES FONDS PROPRES SUR BASE CONSOLIDEE | D1: EP05
A9: Poste mémoire - Déductions applicables aux fonds propres sur base consolidée
A11: Code DISPRU | B11: Poste | C11: Montant | D11: Formules de calcul
B12: A. Immobilisations incorporelles
A13: IM011 | B13: Immobilisations incorporelles | D13: (a)
A14: ID001 | B14: (-) Impôts différés passif associés | D14: (b)
A15: IM012 | B15: Immobilisations incorporelles (nettes d'impôts différés passif) | D15: (c)= a+b
A16: IM013 | B16: Goodwill | D16: (e)
A17: ID002 | B17: (-) Impôts différés passif associés | D17: (f)
A18: IM014 | B18: Goodwill (net d'impôts différés passif) | D18: (g)= e+f
B19: B. Impôts différés actifs
B20: B.1. Impôt différé actif ne dépendant pas de la rentabilité future de l’établissement
A21: ID003 | B21: Total impôt différé actif qui ne dépend pas de la rentabilité future de l'établissement (montant brut) | D21: (a)
A22: ID004 | B22: (-) Impôts différés passif associés | D22: (b)
A23: ID005 | B23: Total impôt différé actif qui ne dépend pas de la rentabilité future de l'établissement (net des impôts différés passif associés) | D23: (c)= a+b
B24: B.2. Impôt différé actif dépendant de la rentabilité future de l’établissement
A25: ID006 | B25: Total impôt différé actif qui dépend de la rentabilité future de l'établissement (montant brut) | D25: (a)
A26: ID007 | B26: (-) Impôts différés passif associés | D26: (b)
A27: ID008 | B27: Total impôt différé actif qui dépend de la rentabilité future de l'établissement (net des impôts différés passif associés); dont | D27: (c)= a+b
A28: ID009 | B28: ne résultant pas de différences temporaires (net au prorata de l'impôt différé passif)
A29: ID010 | B29: résultant de différences temporaires (net au prorata de l'impôt différé passif)
B30: C. Participations
B31: C.1. Détail des participations dans les établissements, les entreprises d'assurance et les autres entités financières
A32: PA150 | B32: Total des participations dans les établissements | D32: (a)
A33: PA151 | B33: Total des participations dans les entreprises d'assurance et les autres entités financières | D33: (b)
A34: PA152 | B34: Total des participations dans les établissements, les entreprises d'assurance et les autres entités financières ; dont | D34: (c)= a+b
A35: PA153 | B35: Participations croisées
A36: PA154 | B36: Participations non significatives (détention de part ≤ 10% ) | D36: (d)
A37: PA155 | B37: Participations significatives (détention de part > 10% ) | D37: (e)
B38: C.2. Participations croisées
A39: PA156 | B39: Eligibles au CET1
A40: PA157 | B40: Eligibles au AT1
A41: PA158 | B41: Eligibles au T2
B42: C.3. Participations non significatives
A43: PA159 | B43: Eligibles au CET1 | D43: (f)
A44: PA160 | B44: Eligibles au AT1 | D44: (g)
A45: PA161 | B45: Eligibles au T2 | D45: (h)
A46: FPC14 | B46: Total des fonds propres CET1 ajustés avant déductions liées à des seuils | D46: (i)
A47: PA162 | B47: Participations non significatives à déduire des fonds propres ; dont | D47: (j)=max[0; (d-0,1*i)]
A48: PA163 | B48: (-) Déduction affectée au CET1 | D48: (k)=j*(f/d)
...

Sheet EP06
A1: DISPOSITIONS TRANSITOIRES SUR BASE CONSOLIDEE : RECLASSEMENT ET RETRAIT PROGRESSIF DES ELEMENTS DE FONDS PROPRES NON ADMISSIBLES | D1: EP06
A9: Code DISPRU | B9: Poste | C9: Montant | D9: Formules de calcul
A10: DT001 | B10: Taux de retrait des éléments de fonds propres non admissibles comptabilisés dans les fonds propres pendant la période de transition | C10: 0.9 | D10: (a)
B12: A. Retrait progressif des instruments de fonds propres de base durs (CET1) non admissibles
A13: FPC01 | B13: Capital social dont ; | D13: (b)
A14: DT002 | B14: Part du capital social non admissibles comme éléments de CET1 au 1er janvier 2018 et les primes d'émission y relatives | D14: (c)
A15: INT29 | B15: Instruments de fonds propres de base durs émis par des filiales consolidées à des tiers en circulation au 1er janvier 2018 et non admissibles comme éléments de CET1 | D15: (d)
A16: DT003 | B16: Provisions réglementées | D16: (e)
A17: DT004 | B17: Fonds affectés | D17: (f)
A18: DT005 | B18: Total des éléments de CET1 non admissibles au 1er janvier 2018 | D18: g=c+d+e+f
A19: DT006 | B19: Montant maximal des éléments de CET1 non admissibles qui peut être inclus dans les fonds propres | D19: h=gxa
A20: DT007 | B20: Montant réel des éléments de CET1 non admissibles en circulation à la date de déclaration | D20: (i)
A21: FPC07 | B21: Eléments de CET1 non admissibles au 1er janvier 2018 et inclus dans le CET1 selon les dispositions transitoires | D21: j=min(h;i)
A22: FPC25 | B22: Instruments de CET1 non admissibles au 1er janvier 2018 et éligibles dans les fonds propres de base additionnels (AT1)
A23: DT008 | B23: Eléments de CET1 non admissibles au 1er janvier 2018 et éligibles dans les fonds propres complémentaires (T2) dont ;
A24: FPC33 | B24: Autres instruments de CET1 non admissibles au 1er janvier 2018 et éligibles dans les fonds propres complémentaires (T2)
A25: FPC35 | B25: Provisions réglementées
A26: FPC36 | B26: Fonds affectés
A27: DT009 | B27: Eléments de CET1 non admissibles au 1er janvier 2018 et exclus des fonds propres.
B29: B. Retrait progressif des éléments de fonds propres complémentaires (T2) non admissibles
A30: DT010 | B30: Emprunts subordonnés en circulation au 1er janvier 2018* dont ; | D30: (k)
A31: DT011 | B31: Part des emprunts subordonnés en circulation au 1er janvier 2018* non admissibles comme élément de fonds propres complémentaires (T2) | D31: (l)
A32: INT30 | B32: Emprunts subordonnés émis par des filiales consolidées à des tiers en circulation au 1er janvier 2018 et non admissibles comme fonds propres T2 | D32: (m)
A33: DT012 | B33: Ecarts de réévaluation | D33: (n)
A34: DT013 | B34: Autres éléments de fonds propres complémentaires (T2) non admissibles au 1er janvier 2018 | D34: (o)
A35: DT014 | B35: Total des éléments de fonds propres complémentaires (T2) non admissibles au 1er janvier 2018 | D35: (p)=l+m+n+o
A36: DT015 | B36: Montant maximal éléments de fonds propres complémentaires (T2) non admissibles qui peut être inclus dans les fonds propres | D36: (q)=pxa
A37: DT016 | B37: Montant réel des éléments de fonds propres complémentaires (T2) non admissibles en circulation à la date de déclaration** | D37: (r)
A38: FPC34 | B38: Eléments de fonds propres complémentaires (T2) non admissibles au 1er janvier 2018 et inclus dans les fonds propres | D38: s=min(q,r)
A40: * après amortissement, s'il y a lieu, jusqu'au 1er janvier 2018
A41: ** après amortissement, s'il y a lieu, jusqu'à la date de déclaration

Sheet EP07
A1: FONDS PROPRES ADMISSIBLES EMIS PAR DES FILIALES ET DETENUS PAR LES INTERETS MINORITAIRES | N1: EP07
A8: Code DISPRU | B8: Formules de calcul | C8: Poste | D8: Total | E8: Fil. 1 | F8: Fil. 2 | G8: Fil. 3 | H8: Fil. 4 | I8: Fil. 5 | J8: Fil. 6 | K8: Fil. 7 | L8: Fil. 8 | M8: Fil. 9 | N8: Fil. 10 | O8: Fil. 11 | P8: Fil. 12 | Q8: Fil. 13 | R8: Fil. 14 | S8: Fil. 15 | T8: Fil. 16 | U8: Fil. 17 | V8: Fil. 18 | W8: Fil. 19 | X8: Fil. 20 | Y8: Fil. 21 | Z8: Fil. 22 | AA8: Fil. 23 | AB8: Fil. 24 | AC8: Fil. 25 | AD8: Fil. 26 | AE8: Fil. 27 | AF8: Fil. 28 | AG8: Fil. 29 | AH8: Fil. 30 | AI8: Fil. 31 | AJ8: Fil. 32 | AK8: Fil. 33 | AL8: Fil. 34 | AM8: Fil. 35 | AN8: Fil. 36 | AO8: Fil. 37 | AP8: Fil. 38 | AQ8: Fil. 39 | AR8: Fil. 40 | AS8: Fil. 41 | AT8: Fil. 42 | AU8: Fil. 43 | AV8: Fil. 44 | AW8: Fil. 45 | AX8: Fil. 46 | AY8: Fil. 47 | AZ8: Fil. 48 | BA8: Fil. 49 | BB8: Fil. 50
A9: INT01 | B9: (a) | C9: Total des fonds propres de base durs (CET1) de la filiale, nets des déductions
A10: INT02 | B10: (b) | C10: Total capital social libéré de la filiale satisfaisant aux critères d'inclusion dans le CET1, plus les réserves, le report à nouveau créditeur et le résultat bénéficiaire appartenant au groupe, avant toutes les déductions
A11: INT03 | B11: (c) | C11: Total capital social libéré de la filiale satisfaisant aux critères d'inclusion dans le CET1, plus les réserves, le report à nouveau créditeur et le résultat bénéficiaire appartenant aux actionnaires minoritaires, avant toutes les déductions
A13: INT04 | B13: (d) | C13: Total des fonds propres de base T1 (fonds propres CET1 + fonds propres AT1) de la filiale, après les déductions
A14: INT05 | B14: (e) | C14: Total des fonds propres de base T1 de la filiale appartenant au groupe avant toutes les déductions
A15: INT06 | B15: (f) | C15: Total des fonds propres de base T1 de la filiale appartenant aux actionnaires minoritaires, avant toutes les déductions
A17: INT07 | B17: (g) | C17: Total des fonds propres (fonds propres CET1 + fonds propres AT1 + fonds propres complémentaires T2) de la filiale, après les déductions
A18: INT08 | B18: (h) | C18: Total des fonds propres de la filiale appartenant au groupe, avant toutes les déductions
A19: INT09 | B19: (i) | C19: Total des fonds propres de la filiale appartenant aux actionnaires minoritaires, avant toutes les déductions
A21: INT10 | B21: (j) | C21: Total des actifs pondérés des risques de la filiale
A22: INT11 | B22: (k) | C22: Actifs pondérés des risques du groupe consolidé se rapportant à la filiale (i.e. actifs pondérés des risques de la filiale, à l'exclusion des transactions intragroupes)
C24: Intérêts minoritaires (CET1)
A25: INT12 | B25: l=jxratio* | C25: Exigence minimale de fonds propres CET1 de la filiale (incluant le coussin de conservation)
A26: INT13 | B26: m=kxratio* | C26: Part de la filiale dans les exigences minimales de fonds propres CET1 du groupe consolidé (incluant le coussin de conservation)
A27: INT14 | B27: n=a-[min(l,m)] | C27: Fonds propres CET1 excédentaires de la filiale
A28: INT15 | B28: o=nxc/(b+c) | C28: Fonds propres CET1 excédentaires appartenant aux actionnaires minoritaires
A29: INT16 | B29: p=[max (0,c-o)] | C29: Intérêts minoritaires à inclure dans le CET1 consolidé ou sous-consolidé
C31: Intérêts minoritaires (AT1)
A32: INT17 | B32: q=jxratio** | C32: Exigence minimale de fonds propres T1 de la filiale (incluant le coussin de conservation)
A33: INT18 | B33: r=kxratio** | C33: Part de la filiale dans les exigences minimales de fonds propres T1 du groupe consolidé (incluant le coussin de conservation)
A34: INT19 | B34: s=d-[min(q,r)] | C34: Fonds propres T1 excédentaires de la filiale
A35: INT20 | B35: t=sxf/(e+f) | C35: Fonds propres T1 excédentaires appartenant aux actionnaires minoritaires
A36: INT21 | B36: u=[max (0,f-t)] | C36: Intérêts minoritaires à inclure dans le T1 consolidé ou sous-consolidé
A37: INT22 | B37: v=u-p | C37: Intérêts minoritaires à inclure dans l'AT1 consolidé ou sous-consolidé
C39: Intérêts minoritaires (T2)
A40: INT23 | B40: w=jxratio*** | C40: Exigence minimale de fonds propres de la filiale (incluant le coussin de conservation)
A41: INT24 | B41: x=kxratio*** | C41: Part de la filiale dans les exigences minimales de fonds propres totaux du groupe consolidé (incluant le coussin de conservation)
A42: INT25 | B42: y=g-[min(w,x)] | C42: Fonds propres totaux excédentaires de la filiale
A43: INT26 | B43: z=yxi/(h+i) | C43: Fonds propres totaux excédentaires appartenant aux actionnaires minoritaires
A44: INT27 | B44: aa=[max (0,i-z)] | C44: Intérêts minoritaires à inclure dans les fonds propres totaux consolidés ou sous-consolidés
A45: INT28 | B45: ab=aa-v-p | C45: Intérêts minoritaires à inclure dans le T2 consolidé ou sous-consolidé
A47: * ratio minimal CET1 (incluant le coussin de conservation)
A48: ** ratio minimal T1 (incluant le coussin de conservation)
A49: *** ratio minimal de solvabilité (incluant le coussin de conservation)

Sheet EP08
A1: TOTAL DES ACTIFS PONDERES DES RISQUES | E1: EP08
A8: Code DISPRU | B8: Poste | D8: Référence | E8: Montant
B9: A. Risque de crédit
A10: RC089 | B10: Expositions sur les souverains | D10: EP12 | E10: ='EP12'!J43
A11: RC114 | B11: Expositions sur les organismes publics hors administration centrale | D11: EP13 | E11: ='EP13'!J43
A12: RC139 | B12: Expositions sur les Banques Multilatérales de développement | D12: EP14 | E12: ='EP14'!J43
A13: RC164 | B13: Expositions sur les institutions financières | D13: EP15 | E13: ='EP15'!J43
A14: RC193 | B14: Expositions sur les entreprises | D14: EP16 | E14: ='EP16'!J47
A15: RC219 | B15: Expositions sur la clientèle de détail | D15: EP17 | E15: ='EP17'!J38
A16: RC239 | B16: Expositions sur les prêts garantis par l'immobilier résidentiel | D16: EP18 | E16: ='EP18'!J35
A17: RC261 | B17: Expositions sur les prêts garantis par l'immobilier commercial | D17: EP19 | E17: ='EP19'!J38
A18: RC276 | B18: Autres actifs | D18: EP20 | E18: =-'EP20'!E27
A19: APR01 | B19: Total – Actifs pondérés du risque de crédit | E19: =E10+E11+E12+E13+E14+E15+E16+E17+E18
B21: B. Risque de marché
A22: RM044 | B22: APR au titre du risque de taux d'intérêt du portefeuille de négociation | D22: EP25 | E22: 0
A23: RM057 | B23: APR au titre du risque de positions sur titre de propriété | D23: EP26 | E23: 0
A24: RM067 | B24: APR au titre du risque de change | D24: EP27 | E24: 0
A25: RM123 | B25: APR au titre du risque de positions sur produits de base | D25: EP28 | E25: 0
A26: APR02 | B26: Total – Actifs pondérés du risque de marché | E26: 0
B28: C. Risque opérationnel
B29: Actifs pondérés du risque selon ;
A30: RO010 | B30: - l'approche indicateur de base | D30: EP21 | E30: ='EP21'!I26
A31: RO037 | B31: - l'approche standard | D31: EP23
A32: APR03 | B32: Total – Actifs pondérés du risque opérationnel | E32: =E30+E31
A34: APR04 | B34: TOTAL ACTIFS PONDERES DES RISQUES (APR) | E34: =E19+E26+E32

Sheet EP09
A1: VENTILATION DU BILAN ENTRE LES DIFFERENTES CATEGORIES D'EXPOSITION | I1: EP09
A8: Code DISPRU | B8: Poste | D8: Expositions brutes | G8: (-) Provisions | H8: (-) Eléments déduits des fonds propres | I8: Expositions nettes
E9: Dont ; Créances en souffrances | F9: Dont ; Créances à risque élevé
D10: (a) | E10: (b) | F10: (c) | G10: (d) | H10: (e) | I10: (f) = a + d + e
B11: Expositions au bilan soumises au risque de crédit
A12: RC001 | I12: =D12-G12-H12
A13: RC002 | I13: =D13-G13-H13
A14: RC003 | I14: =D14-G14-H14
A15: RC004 | I15: =D15-G15-H15
A16: RC005 | B16: Expositions sur les entreprises; dont : | D16: =D17+D18 | E16: =E17+E18 | F16: =F17+F18 | G16: =G17+G18 | H16: =H17+H18 | I16: =D16-G16-H16
A17: RC006 | I17: =D17-G17-H17
A18: RC007 | D18: =-203717+173 | I18: =D18-G18-H18
A19: RC008 | B19: Expositions sur la clientèle de détail; dont : | D19: =D20+D21 | E19: =E20+E21 | F19: =F20+F21 | G19: =G20+G21 | H19: =H20+H21 | I19: =D19-G19-H19
A20: RC009 | I20: =D20-G20-H20
A21: RC010 | D21: =-19462+960 | F21: =F22+F23 | I21: =D21-G21-H21
A22: RC011 | D22: =-1737-1133 | I22: =D22-G22-H22
A23: RC012 | B23: Expositions sur les prêts garantis par l'immobilier commercial; dont : | D23: =D24+D25 | E23: =E24+E25 | F23: =F24+F25 | G23: =G24+G25 | H23: =H24+H25 | I23: =D23-G23-H23
A24: RC013 | I24: =D24-G24-H24
A25: RC014 | I25: =D25-G25-H25
A26: RC015 | I26: =D26-G26-H26
A28: RC016 | D28: =D12+D13+D14+D15+D16+D19+D22+D23+D26 | E28: =E12+E13+E14+E15+E16+E19+E22+E23+E26 | F28: =F12+F13+F14+F15+F16+F19+F22+F23+F26 | G28: =G12+G13+G14+G15+G16+G19+G22+G23+G26 | H28: =H12+H13+H14+H15+H16+H19+H22+H23+H26 | I28: =I12+I13+I14+I15+I16+I19+I22+I23+I26

Sheet EP10
A1: VENTILATION DES ENGAGEMENTS HORS BILAN ENTRE LES DIFFERENTES CATEGORIES D'EXPOSITION (HORS DERIVES) | N1: EP10
A8: Code DISPRU | B8: Poste | D8: Expositions brutes avant FCEC | G8: Répartition des expositions brutes par FCEC applicables | L8: Expositions brutes après FCEC | M8: (-) Provisions | N8: Expositions nettes
E9: Dont ; Créances en souffrances | F9: Dont ; Créances à risque élevé | G9: 0.1 | H9: 0.2 | I9: 0.5 | J9: 0.75 | K9: 1
D10: (a) | E10: (b) | F10: (c) | G10: (d) | H10: (e) | I10: (f) | J10: (g) | K10: (h) | L10: (i) = a - (0 ,9 x d) - (0,8 x e) - (0,5 x f) - (0,25 x g) | M10: (j) | N10: (k) = i + j
B11: Engagement de financement soumis au risque de crédit
A12: RC017
A13: RC018
A14: RC019
A15: RC020 | I15: =D15 | L15: =I15*0.5 | N15: =L15+M15
A16: RC021 | B16: Expositions sur les entreprises; dont : | D16: =D17+D18 | E16: =E17+E18 | F16: =F17+F18 | G16: =G17+G18 | H16: =H17+H18 | I16: =I17+I18 | J16: =J17+J18 | K16: =K17+K18 | ... N16: =N17+N18
A17: RC022
A18: RC023 | I18: =D18 | L18: =I18*0.5 | N18: =L18+M18
A19: RC024 | D19: =D20+D21 | E19: =E20+E21 | F19: =F20+F21 | G19: =G20+G21 | H19: =H20+H21 | I19: =I20+I21 | J19: =J20+J21 | K19: =K20+K21 | ... N19: =N20+N21
A20: RC025
A21: RC026 | I21: =D21 | L21: =I21*0.5 | N21: =L21+M21
A22: RC027
A23: RC028 | D23: =D24+D25 | E23: =E24+E25 | F23: =F24+F25 | G23: =G24+G25 | H23: =H24+H25 | I23: =I24+I25 | J23: =J24+J25 | K23: =K24+K25 | ... N23: =N24+N25
A24: RC029
A25: RC030 | I25: =D25 | L25: =I25*0.5 | N25: =L25+M25
A26: RC031
A28: RC032 | D28: =D12+D13+D14+D15+D16+D19+D22+D23+D26 | E28: =E12+E13+E14+E15+E16+E19+E22+E23+E26 | F28: =F12+F13+F14+F15+F16+F19+F22+F23+F26 | G28: =G12+G13+G14+G15+G16+G19+G22+G23+G26 | H28: =H12+H13+H14+H15+H16+H19+H22+H23+H26 | I28: =I12+I13+I14+I15+I16+I19+I22+I23+I26 | J28: =J12+J13+J14+J15+J16+J19+J22+J23+J26 | K28: =K12+K13+K14+K15+K16+K19+K22+K23+K26 | ... N28: =N12+N13+N14+N15+N16+N19+N22+N23+N26
A31: RC033
A32: RC034
A33: RC035
A34: RC036 | I34: =D34 | L34: =I34*0.5 | N34: =L34+M34
A35: RC037 | B35: Expositions sur les entreprises; dont : | D35: =D36+D37 | E35: =E36+E37 | F35: =F36+F37 | G35: =G36+G37 | H35: =H36+H37 | I35: =I36+I37 | J35: =J36+J37 | K35: =K36+K37 | ... N35: =N36+N37
A36: RC038
A37: RC039 | I37: =D37 | L37: =I37*0.5 | N37: =L37+M37
A38: RC040 | D38: =D39+D40 | E38: =E39+E40 | F38: =F39+F40 | G38: =G39+G40 | H38: =H39+H40 | I38: =I39+I40 | J38: =J39+J40 | K38: =K39+K40 | ... N38: =N39+N40
A39: RC041
A40: RC042 | I40: =D40 | L40: =I40*0.5 | N40: =L40+M40
A41: RC043
A42: RC044 | D42: =D43+D44 | E42: =E43+E44 | F42: =F43+F44 | G42: =G43+G44 | H42: =H43+H44 | I42: =I43+I44 | J42: =J43+J44 | K42: =K43+K44 | ... N42: =N43+N44
A43: RC045
A44: RC046 | I44: =D44 | L44: =I44*0.5 | N44: =L44+M44
A45: RC047
A47: RC048 | B47: TOTAL EXPOSITIONS SUR LES AUTRES ENGAGEMENTS HORS-BILAN (EXCLUANT LES DERIVES) | D47: =D31+D32+D33+D34+D35+D38+D41+D42+D45 | E47: =E31+E32+E33+E34+E35+E38+E41+E42+E45 | F47: =F31+F32+F33+F34+F35+F38+F41+F42+F45 | G47: =G31+G32+G33+G34+G35+G38+G41+G42+G45 | H47: =H31+H32+H33+H34+H35+H38+H41+H42+H45 | I47: =I31+I32+I33+I34+I35+I38+I41+I42+I45 | J47: =J31+J32+J33+J34+J35+J38+J41+J42+J45 | K47: =K31+K32+K33+K34+K35+K38+K41+K42+K45 | ... N47: =N31+N32+N33+N34+N35+N38+N41+N42+N45

Sheet EP11
A1: EXPOSITIONS AU RISQUE DE CONTREPARTIE | L1: EP11
A8: Code DISPRU | B8: Poste | C8: Coût de remplacement au prix du marché | D8: Montant notionnel des contrats | E8: Pondération affectée au montant notionnel des contrats | F8: Montant notionnel des contrats pondéré | G8: Expositions | H8: Ventilation des expositions brutes par catégorie
H9: Souverains | I9: Organismes publics hors administration centrale | J9: Banques Multilatérales de développement | K9: Institutions financières | L9: Entreprises
C10: (a) | D10: (b) | E10: (c) | F10: d=b x c | G10: e= a + d
B11: Engagements sur instruments de taux d'intérêt
A12: RC049 | B12: - Durée < 1 an | C12: 0 | D12: 0 | E12: 0 | F12: 0 | G12: 0
A13: RC050 | B13: - Durée > 1 an jusqu'à 5 ans | C13: 0 | D13: 0 | E13: 0,5 % | F13: 0 | G13: 0
A14: RC051 | B14: - Durée > 5 ans | C14: 0 | D14: 0 | E14: 1,5 % | F14: 0 | G14: 0
B16: Engagements sur instruments de taux de change et l'or
A17: RC052 | B17: - Durée < 1 an | C17: 0 | D17: 0 | E17: 1% | F17: 0 | G17: 0
A18: RC053 | B18: - Durée > 1 an jusqu'à 5 ans | C18: 0 | D18: 0 | E18: 5 % | F18: 0 | G18: 0
A19: RC054 | B19: - Durée > 5 ans | C19: 0 | D19: 0 | E19: 7,5 % | F19: 0 | G19: 0
B21: Engagements sur titres de propriété
A22: RC055 | B22: - Durée < 1 an | C22: 0 | D22: 0 | E22: 6% | F22: 0 | G22: 0
A23: RC056 | B23: - Durée > 1 an jusqu'à 5 ans | C23: 0 | D23: 0 | E23: 8% | F23: 0 | G23: 0
A24: RC057 | B24: - Durée > 5 ans | C24: 0 | D24: 0 | E24: 0.1 | F24: 0 | G24: 0
B26: Engagements sur métaux précieux (excepté l'or)
A27: RC058 | B27: - Durée < 1 an | C27: 0 | D27: 0 | E27: 7% | F27: 0 | G27: 0
A28: RC059 | B28: - Durée > 1 an jusqu'à 5 ans | C28: 0 | D28: 0 | E28: 7% | F28: 0 | G28: 0
A29: RC060 | B29: - Durée > 5 ans | C29: 0 | D29: 0 | E29: 0.08 | F29: 0 | G29: 0
B31: Engagements sur autres produits de base
A32: RC061 | B32: - Durée < 1 an | C32: 0 | D32: 0 | E32: 10% | F32: 0 | G32: 0
A33: RC062 | B33: - Durée > 1 an jusqu'à 5 ans | C33: 0 | D33: 0 | E33: 12% | F33: 0 | G33: 0
A34: RC063 | B34: - Durée > 5 ans | C34: 0 | D34: 0 | E34: 0.15 | F34: 0 | G34: 0
A36: RC064 | B36: TOTAL | C36: 0 | D36: 0 | F36: 0 | G36: 0 | H36: 0 | I36: 0 | J36: 0 | K36: 0 | L36: 0

Sheet EP12
B1: RISQUE DE CREDIT : EXPOSITIONS SUR LES SOUVERAINS | J1: EP12
A8: Code DISPRU | B8: Coefficient de pondération | C8: Avant ARC | D8: Ajustements pour ARC (approche simple) | G8: Ajustements pour ARC (approche globale) | I8: Après ARC | J8: Actifs pondérés des risques
C9: Expositions nettes | D9: (+/-) Garanties | E9: (+/-) Dérivés de crédit | F9: (+/-) Sûretés financières | G9: Ajustement lié à la valeur de l'exposition | H9: (-) Valeur ajustée de la sûreté | I9: Expositions nettes
B10: (a)
B11: Expositions au bilan
A12: RC065 | B12: 0 | I12: =C12+D12+E12+F12+G12+H12
A13: RC066 | B13: 0.2 | I13: =C13+D13+E13+F13+G13+H13 | J13: =I13*B13
A14: RC067 | B14: 0.5 | I14: =C14+D14+E14+F14+G14+H14 | J14: =I14*B14
A15: RC068 | B15: 1 | I15: =C15+D15+E15+F15+G15+H15 | J15: =I15*B15
A16: RC069 | B16: 1.5 | I16: =C16+D16+E16+F16+G16+H16 | J16: =I16*B16
A17: RC070 | B17: Total | C17: =C12+C13+C14+C15+C16 | D17: =D12+D13+D14+D15+D16 | E17: =E12+E13+E14+E15+E16 | F17: =F12+F13+F14+F15+F16 | G17: =G12+G13+G14+G15+G16 | H17: =H12+H13+H14+H15+H16 | I17: =I12+I13+I14+I15+I16 | J17: =J12+J13+J14+J15+J16
B19: Engagements de financement (hors bilan)
A20: RC071 | B20: 0
A21: RC072 | B21: 0.2
A22: RC073 | B22: 0.5
A23: RC074 | B23: 1
A24: RC075 | B24: 1.5
A25: RC076 | B25: Total
B27: Autres engagements de hors-bilan
A28: RC077 | B28: 0
A29: RC078 | B29: 0.2
A30: RC079 | B30: 0.5
A31: RC080 | B31: 1
A32: RC081 | B32: 1.5
A33: RC082 | B33: Total
B35: Expositions soumises au risque de contrepartie
A36: RC083 | B36: 0
A37: RC084 | B37: 0.2
A38: RC085 | B38: 0.5
A39: RC086 | B39: 1
A40: RC087 | B40: 1.5
A41: RC088 | B41: Total
A43: RC089 | B43: TOTAL EXPOSITIONS SUR LES SOUVERAINS | C43: =C17+C25+C33+C41 | D43: =D17+D25+D33+D41 | E43: =E17+E25+E33+E41 | F43: =F17+F25+F33+F41 | G43: =G17+G25+G33+G41 | H43: =H17+H25+H33+H41 | I43: =I17+I25+I33+I41 | J43: =J17+J25+J33+J41

Sheet EP13
B1: RISQUE DE CREDIT : EXPOSITIONS SUR LES ORGANISMES PUBLICS HORS ADMINISTRATION CENTRALE (OP) | J1: EP13
A8: Code DISPRU | B8: Coefficient de pondération | C8: Avant ARC | D8: Ajustements pour ARC (approche simple) | G8: Ajustements pour ARC (approche globale) | I8: Après ARC | J8: Actifs pondérés des risques
C9: Expositions nettes | D9: (+/-) Garanties | E9: (+/-) Dérivés de crédit | F9: (+/-) Sûretés financières | G9: Ajustement lié à la valeur de l'exposition | H9: (-) Valeur ajustée de la sûreté | I9: Expositions nettes
B10: (a)
B11: Expositions au bilan
A12: RC090 | B12: 0 | I12: =C12+D12+E12+F12+G12+H12
A13: RC091 | B13: 0.2 | I13: =C13+D13+E13+F13+G13+H13 | J13: =I13*B13
A14: RC092 | B14: 0.5 | I14: =C14+D14+E14+F14+G14+H14 | J14: =I14*B14
A15: RC093 | B15: 1 | I15: =C15+D15+E15+F15+G15+H15 | J15: =I15*B15
A16: RC094 | B16: 1.5 | I16: =C16+D16+E16+F16+G16+H16 | J16: =I16*B16
A17: RC095 | B17: Total | C17: =C12+C13+C14+C15+C16 | D17: =D12+D13+D14+D15+D16 | E17: =E12+E13+E14+E15+E16 | F17: =F12+F13+F14+F15+F16 | G17: =G12+G13+G14+G15+G16 | H17: =H12+H13+H14+H15+H16 | I17: =I12+I13+I14+I15+I16 | J17: =J12+J13+J14+J15+J16
B19: Engagements de financement (hors bilan)
A20: RC096 | B20: 0
A21: RC097 | B21: 0.2
A22: RC098 | B22: 0.5
A23: RC099 | B23: 1
A24: RC100 | B24: 1.5
A25: RC101 | B25: Total
B27: Autres engagements de hors-bilan
A28: RC102 | B28: 0
A29: RC103 | B29: 0.2
A30: RC104 | B30: 0.5
A31: RC105 | B31: 1
A32: RC106 | B32: 1.5
A33: RC107 | B33: Total
B35: Expositions soumises au risque de contrepartie
A36: RC108 | B36: 0
A37: RC109 | B37: 0.2
A38: RC110 | B38: 0.5
A39: RC111 | B39: 1
A40: RC112 | B40: 1.5
A41: RC113 | B41: Total
A43: RC114 | B43: TOTAL EXPOSITIONS SUR LES OP | C43: =C17+C25+C33+C41 | D43: =D17+D25+D33+D41 | E43: =E17+E25+E33+E41 | F43: =F17+F25+F33+F41 | G43: =G17+G25+G33+G41 | H43: =H17+H25+H33+H41 | I43: =I17+I25+I33+I41 | J43: =J17+J25+J33+J41

Sheet EP14
B1: RISQUE DE CREDIT : EXPOSITIONS SUR LES BANQUES MULTILATERALES DE DEVELOPPEMENT (BMD) | J1: EP14
A8: Code DISPRU | B8: Coefficient de pondération | C8: Avant ARC | D8: Ajustements pour ARC (approche simple) | G8: Ajustements pour ARC (approche globale) | I8: Après ARC | J8: Actifs pondérés des risques
C9: Expositions nettes | D9: (+/-) Garanties | E9: (+/-) Dérivés de crédit | F9: (+/-) Sûretés financières | G9: Ajustement lié à la valeur de l'exposition | H9: (-) Valeur ajustée de la sûreté | I9: Expositions nettes
B10: (a)
B11: Expositions au bilan
A12: RC115 | B12: 0
A13: RC116 | B13: 0.2
A14: RC117 | B14: 0.5
A15: RC118 | B15: 1
A16: RC119 | B16: 1.5
A17: RC120 | B17: Total
B19: Engagements de financement (hors bilan)
A20: RC121 | B20: 0
A21: RC122 | B21: 0.2
A22: RC123 | B22: 0.5
A23: RC124 | B23: 1
A24: RC125 | B24: 1.5
A25: RC126 | B25: Total
B27: Autres engagements de hors-bilan
A28: RC127 | B28: 0
A29: RC128 | B29: 0.2
A30: RC129 | B30: 0.5
A31: RC130 | B31: 1
A32: RC131 | B32: 1.5
A33: RC132 | B33: Total
B35: Expositions soumises au risque de contrepartie
A36: RC133 | B36: 0
A37: RC134 | B37: 0.2
A38: RC135 | B38: 0.5
A39: RC136 | B39: 1
A40: RC137 | B40: 1.5
A41: RC138 | B41: Total
A43: RC139 | B43: TOTAL EXPOSITIONS SUR LES BMD

Sheet EP15
B1: RISQUE DE CREDIT : EXPOSITIONS SUR LES INSTITUTIONS FINANCIERES (IF) | J1: EP15
A8: Code DISPRU | B8: Coefficient de pondération | C8: Avant ARC | D8: Ajustements pour ARC (approche simple) | G8: Ajustements pour ARC (approche globale) | I8: Après ARC | J8: Actifs pondérés des risques
C9: Expositions nettes | D9: (+/-) Garanties | E9: (+/-) Dérivés de crédit | F9: (+/-) Sûretés financières | G9: Ajustement lié à la valeur de l'exposition | H9: (-) Valeur ajustée de la sûreté | I9: Expositions nettes
B10: (a)
B11: Expositions au bilan
A12: RC140 | B12: 0 | I12: =H12+G12+F12+E12+D12+C12
A13: RC141 | B13: 0.2 | I13: =H13+G13+F13+E13+D13+C13 | J13: =I13*B13
A14: RC142 | B14: 0.5 | I14: =H14+G14+F14+E14+D14+C14 | J14: =I14*B14
A15: RC143 | B15: 1 | I15: =H15+G15+F15+E15+D15+C15 | J15: =I15*B15
A16: RC144 | B16: 1.5 | I16: =H16+G16+F16+E16+D16+C16 | J16: =I16*B16
A17: RC145 | B17: Total | C17: =C12+C13+C14+C15+C16 | D17: =D12+D13+D14+D15+D16 | E17: =E12+E13+E14+E15+E16 | F17: =F12+F13+F14+F15+F16 | G17: =G12+G13+G14+G15+G16 | H17: =H12+H13+H14+H15+H16 | I17: =I12+I13+I14+I15+I16 | J17: =J12+J13+J14+J15+J16
B19: Engagements de financement (hors bilan)
A20: RC146 | B20: 0
A21: RC147 | B21: 0.2
A22: RC148 | B22: 0.5
A23: RC149 | B23: 1
A24: RC150 | B24: 1.5
A25: RC151 | B25: Total
B27: Autres engagements de hors-bilan
A28: RC152 | B28: 0 | I28: =H28+G28+F28+E28+D28+C28
A29: RC153 | B29: 0.2 | I29: =H29+G29+F29+E29+D29+C29 | J29: =I29*B29
A30: RC154 | B30: 0.5 | C30: ='EP10'!N34 | I30: =H30+G30+F30+E30+D30+C30 | J30: =I30*B30
A31: RC155 | B31: 1 | I31: =H31+G31+F31+E31+D31+C31 | J31: =I31*B31
A32: RC156 | B32: 1.5 | I32: =H32+G32+F32+E32+D32+C32 | J32: =I32*B32
A33: RC157 | B33: Total | C33: =C28+C29+C30+C31+C32 | D33: =D28+D29+D30+D31+D32 | E33: =E28+E29+E30+E31+E32 | F33: =F28+F29+F30+F31+F32 | G33: =G28+G29+G30+G31+G32 | H33: =H28+H29+H30+H31+H32 | I33: =I28+I29+I30+I31+I32 | J33: =J28+J29+J30+J31+J32
B35: Expositions soumises au risque de contrepartie
A36: RC158 | B36: 0
A37: RC159 | B37: 0.2
A38: RC160 | B38: 0.5
A39: RC161 | B39: 1
A40: RC162 | B40: 1.5
A41: RC163 | B41: Total
A43: RC164 | B43: TOTAL EXPOSITIONS SUR LES IF | C43: =C17+C25+C33+C41 | D43: =D17+D25+D33+D41 | E43: =E17+E25+E33+E41 | F43: =F17+F25+F33+F41 | G43: =G17+G25+G33+G41 | H43: =H17+H25+H33+H41 | I43: =I17+I25+I33+I41 | J43: =J17+J25+J33+J41

Sheet EP16
B1: RISQUE DE CREDIT : EXPOSITIONS SUR LES ENTREPRISES | J1: EP16
A8: Code DISPRU | B8: Coefficient de pondération | C8: Avant ARC | D8: Ajustements pour ARC (approche simple) | G8: Ajustements pour ARC (approche globale) | I8: Après ARC | J8: Actifs pondérés des risques
C9: Expositions nettes | D9: (+/-) Garanties | E9: (+/-) Dérivés de crédit | F9: (+/-) Sûretés financières | G9: Ajustement lié à la valeur de l'exposition | H9: (-) Valeur ajustée de la sûreté | I9: Expositions nettes
B10: (a)
B11: Expositions au bilan
A12: RC165 | B12: 0 | I12: =H12+G12+F12+E12+D12+C12
A13: RC166 | B13: 0.2 | I13: =H13+G13+F13+E13+D13+C13 | J13: =I13*B13
A14: RC167 | B14: 0.5 | I14: =H14+G14+F14+E14+D14+C14 | J14: =I14*B14
A15: RC168 | B15: 0.75 | I15: =H15+G15+F15+E15+D15+C15 | J15: =I15*B15
A16: RC169 | B16: 1 | C16: =199344-173 | D16: =-(D12+D13+D14) | I16: =H16+G16+F16+E16+D16+C16 | J16: =I16*B16
A17: RC170 | B17: 1.5 | I17: =H17+G17+F17+E17+D17+C17 | J17: =I17*B17
A18: RC171 | B18: Total | C18: =C17+C16+C14+C15+C12+C13 | D18: =D17+D16+D14+D15+D12+D13 | E18: =E17+E16+E14+E15+E12+E13 | F18: =F17+F16+F14+F15+F12+F13 | G18: =G17+G16+G14+G15+G12+G13 | H18: =H17+H16+H14+H15+H12+H13 | I18: =I17+I16+I14+I15+I12+I13 | J18: =J17+J16+J14+J15+J12+J13
B20: Engagements de financement (hors bilan)
A21: RC172 | B21: 0 | I21: =H21+G21+F21+E21+D21+C21
A22: RC173 | B22: 0.2 | I22: =H22+G22+F22+E22+D22+C22 | J22: =I22*B22
A23: RC174 | B23: 0.5 | I23: =H23+G23+F23+E23+D23+C23 | J23: =I23*B23
A24: RC175 | B24: 0.75 | I24: =H24+G24+F24+E24+D24+C24 | J24: =I24*B24
A25: RC176 | B25: 1 | C25: ='EP10'!N16 | I25: =H25+G25+F25+E25+D25+C25 | J25: =I25*B25
A26: RC177 | B26: 1.5 | I26: =H26+G26+F26+E26+D26+C26 | J26: =I26*B26
A27: RC178 | B27: Total | C27: =C26+C25+C23+C24+C21+C22 | D27: =D26+D25+D23+D24+D21+D22 | E27: =E26+E25+E23+E24+E21+E22 | F27: =F26+F25+F23+F24+F21+F22 | G27: =G26+G25+G23+G24+G21+G22 | H27: =H26+H25+H23+H24+H21+H22 | I27: =I26+I25+I23+I24+I21+I22 | J27: =J26+J25+J23+J24+J21+J22
B29: Autres engagements de hors-bilan
A30: RC179 | B30: 0 | I30: =H30+G30+F30+E30+D30+C30
A31: RC180 | B31: 0.2 | I31: =H31+G31+F31+E31+D31+C31 | J31: =I31*B31
A32: RC181 | B32: 0.5 | I32: =H32+G32+F32+E32+D32+C32 | J32: =I32*B32
A33: RC182 | B33: 0.75 | I33: =H33+G33+F33+E33+D33+C33 | J33: =I33*B33
A34: RC183 | B34: 1 | C34: ='EP10'!N35 | I34: =H34+G34+F34+E34+D34+C34 | J34: =I34*B34
A35: RC184 | B35: 1.5 | I35: =H35+G35+F35+E35+D35+C35 | J35: =I35*B35
A36: RC185 | B36: Total | C36: =C35+C34+C32+C33+C30+C31 | D36: =D35+D34+D32+D33+D30+D31 | E36: =E35+E34+E32+E33+E30+E31 | F36: =F35+F34+F32+F33+F30+F31 | G36: =G35+G34+G32+G33+G30+G31 | H36: =H35+H34+H32+H33+H30+H31 | I36: =I35+I34+I32+I33+I30+I31 | J36: =J35+J34+J32+J33+J30+J31
B38: Expositions soumises au risque de contrepartie
A39: RC186 | B39: 0
A40: RC187 | B40: 0.2
A41: RC188 | B41: 0.5
A42: RC189 | B42: 0.75
A43: RC190 | B43: 1
A44: RC191 | B44: 1.5
A45: RC192 | B45: Total
A47: RC193 | B47: TOTAL EXPOSITIONS SUR LES ENTREPRISES | C47: =C18+C27+C36+C45 | D47: =D18+D27+D36+D45 | E47: =E18+E27+E36+E45 | F47: =F18+F27+F36+F45 | G47: =G18+G27+G36+G45 | H47: =H18+H27+H36+H45 | I47: =I18+I27+I36+I45 | J47: =J18+J27+J36+J45
A50: Poste mémoire - Expositions déclassées dans la catégorie Entreprises
A52: Code DISPRU | B52: Poste | I52: Exposition nette après ARC | J52: Actifs pondérés des risques
A53: RC194 | B53: Expositions sur les organismes publics hors administration centrale | I53: ='EP13'!I43 | J53: ='EP13'!J43
...

Sheet EP17
B1: RISQUE DE CREDIT : EXPOSITIONS SUR LA CLIENTELE DE DETAIL | J1: EP17
A8: Code DISPRU | B8: Coefficient de pondération | C8: Avant ARC | D8: Ajustements pour ARC (approche simple) | G8: Ajustements pour ARC (approche globale) | I8: Après ARC | J8: Actifs pondérés des risques
C9: Expositions nettes | D9: (+/-) Garanties | E9: (+/-) Dérivés de crédit | F9: (+/-) Sûretés financières | G9: Ajustement lié à la valeur de l'exposition | H9: (-) Valeur ajustée de la sûreté | I9: Expositions nettes
B10: (a)
B11: Expositions au bilan
A12: RC198 | B12: 0 | I12: =H12+G12+F12+E12+D12+C12
A13: RC199 | B13: 0.2 | I13: =H13+G13+F13+E13+D13+C13 | J13: =I13*B13
A14: RC200 | B14: 0.5 | I14: =H14+G14+F14+E14+D14+C14 | J14: =I14*B14
A15: RC201 | B15: 0.75 | C15: =17932-960 | I15: =H15+G15+F15+E15+D15+C15 | J15: =I15*B15
A16: RC202 | B16: 1 | I16: =H16+G16+F16+E16+D16+C16 | J16: =I16*B16
A17: RC203 | B17: 1.5 | I17: =H17+G17+F17+E17+D17+C17 | J17: =I17*B17
A18: RC204 | B18: Total | C18: =C12+C13+C14+C15+C16+C17 | D18: =D12+D13+D14+D15+D16+D17 | E18: =E12+E13+E14+E15+E16+E17 | F18: =F12+F13+F14+F15+F16+F17 | G18: =G12+G13+G14+G15+G16+G17 | H18: =H12+H13+H14+H15+H16+H17 | I18: =I12+I13+I14+I15+I16+I17 | J18: =J12+J13+J14+J15+J16+J17
B20: Engagements de financement (hors bilan)
A21: RC205 | B21: 0
A22: RC206 | B22: 0.2
A23: RC207 | B23: 0.5
A24: RC208 | B24: 0.75
A25: RC209 | B25: 1
A26: RC210 | B26: 1.5
A27: RC211 | B27: Total
B29: Autres engagements de hors-bilan
A30: RC212 | B30: 0 | I30: =H30+G30+F30+E30+D30+C30
A31: RC213 | B31: 0.2 | I31: =H31+G31+F31+E31+D31+C31 | J31: =I31*B31
A32: RC214 | B32: 0.5 | I32: =H32+G32+F32+E32+D32+C32 | J32: =I32*B32
A33: RC215 | B33: 0.75 | C33: ='EP10'!N38 | I33: =H33+G33+F33+E33+D33+C33 | J33: =I33*B33
A34: RC216 | B34: 1 | I34: =H34+G34+F34+E34+D34+C34 | J34: =I34*B34
A35: RC217 | B35: 1.5 | I35: =H35+G35+F35+E35+D35+C35 | J35: =I35*B35
A36: RC218 | B36: Total | C36: =C30+C31+C32+C33+C34+C35 | D36: =D30+D31+D32+D33+D34+D35 | E36: =E30+E31+E32+E33+E34+E35 | F36: =F30+F31+F32+F33+F34+F35 | G36: =G30+G31+G32+G33+G34+G35 | H36: =H30+H31+H32+H33+H34+H35 | I36: =I30+I31+I32+I33+I34+I35 | J36: =J30+J31+J32+J33+J34+J35
A38: RC219 | B38: TOTAL EXPOSITIONS SUR LA CLIENTELE DE DETAIL | C38: =C18+C27+C36 | D38: =D18+D27+D36 | E38: =E18+E27+E36 | F38: =F18+F27+F36 | G38: =G18+G27+G36 | H38: =H18+H27+H36 | I38: =I18+I27+I36 | J38: =J18+J27+J36
A41: Poste mémoire - Expositions déclassées dans la catégorie clientèle de détail
A43: Code DISPRU | B43: Poste
A44: RC220 | B44: Expositions sur les prêts garantis par l'immobilier résidentiel | I44: ='EP18'!I35 | J44: ='EP18'!J35

Sheet EP18
B1: RISQUE DE CREDIT : EXPOSITIONS SUR LES PRÊTS GARANTIS PAR L'IMMOBILIER RESIDENTIEL (PG/IR) | J1: EP18
A8: Code DISPRU | B8: Coefficient de pondération | C8: Avant ARC | D8: Ajustements pour ARC (approche simple) | G8: Ajustements pour ARC (approche globale) | I8: Après ARC | J8: Actifs pondérés des risques
C9: Expositions nettes | D9: (+/-) Garanties | E9: (+/-) Dérivés de crédit | F9: (+/-) Sûretés financières | G9: Ajustement lié à la valeur de l'exposition | H9: (-) Valeur ajustée de la sûreté | I9: Expositions nettes
B10: (a)
B11: Expositions au bilan
A12: RC221 | B12: 0
A13: RC222 | B13: 0.2
A14: RC223 | B14: 0.35 | C14: =1644+1133 | I14: =H14+G14+F14+E14+D14+C14 | J14: =I14*B14
A15: RC224 | B15: 0.5
A16: RC225 | B16: 1 | I16: =H16+G16+F16+E16+D16+C16 | J16: =I16*B16
A17: RC226 | B17: Total | C17: =C12+C13+C14+C15+C16 | D17: =D12+D13+D14+D15+D16 | E17: =E12+E13+E14+E15+E16 | F17: =F12+F13+F14+F15+F16 | G17: =G12+G13+G14+G15+G16 | H17: =H12+H13+H14+H15+H16 | I17: =I12+I13+I14+I15+I16 | J17: =J12+J13+J14+J15+J16
B19: Engagements de financement (hors bilan)
A20: RC227 | B20: 0
A21: RC228 | B21: 0.2
A22: RC229 | B22: 0.35
A23: RC230 | B23: 0.5
A24: RC231 | B24: 1
A25: RC232 | B25: Total
B27: Autres engagements de hors-bilan
A28: RC233 | B28: 0
A29: RC234 | B29: 0.2
A30: RC235 | B30: 0.35
A31: RC236 | B31: 0.5
A32: RC237 | B32: 1
A33: RC238 | B33: Total
A35: RC239 | B35: TOTAL EXPOSITIONS SUR LES PG/IR | C35: =C17+C25+C33 | D35: =D17+D25+D33 | E35: =E17+E25+E33 | F35: =F17+F25+F33 | G35: =G17+G25+G33 | H35: =H17+H25+H33 | I35: =I17+I25+I33 | J35: =J17+J25+J33

Sheet EP19
B1: RISQUE DE CREDIT : EXPOSITIONS SUR LES PRÊTS GARANTIS PAR L'IMMOBILIER COMMERCIAL (PG/IC) | J1: EP19
A8: Code DISPRU | B8: Coefficient de pondération | C8: Avant ARC | D8: Ajustements pour ARC (approche simple) | G8: Ajustements pour ARC (approche globale) | I8: Après ARC | J8: Actifs pondérés des risques
C9: Exposition nette | D9: (+/-) Garanties | E9: (+/-) Dérivés de crédit | F9: (+/-) Sûretés financières | G9: Ajustement lié à la valeur de l'exposition | H9: (-) Valeur ajustée de la sûreté | I9: Expositions nettes
B10: (a)
B11: Expositions au bilan
A12: RC240 | B12: 0
A13: RC241 | B13: 0.2
A14: RC242 | B14: 0.5
A15: RC243 | B15: 0.75 | I15: =H15+G15+F15+E15+D15+C15 | J15: =I15*B15
A16: RC244 | B16: 1 | I16: =H16+G16+F16+E16+D16+C16 | J16: =I16*B16
A17: RC245 | B17: 1.5 | I17: =H17+G17+F17+E17+D17+C17 | J17: =I17*B17
A18: RC246 | B18: Total | C18: =C12+C13+C14+C15+C16+C17 | D18: =D12+D13+D14+D15+D16+D17 | E18: =E12+E13+E14+E15+E16+E17 | F18: =F12+F13+F14+F15+F16+F17 | G18: =G12+G13+G14+G15+G16+G17 | H18: =H12+H13+H14+H15+H16+H17 | I18: =I12+I13+I14+I15+I16+I17 | J18: =J12+J13+J14+J15+J16+J17
B20: Engagements de financement (hors bilan)
A21: RC247 | B21: 0
A22: RC248 | B22: 0.2
A23: RC249 | B23: 0.5
A24: RC250 | B24: 0.75
A25: RC251 | B25: 1
A26: RC252 | B26: 1.5
A27: RC253 | B27: Total
B29: Autres engagements de hors-bilan
A30: RC254 | B30: 0
A31: RC255 | B31: 0.2
A32: RC256 | B32: 0.5
A33: RC257 | B33: 0.75 | C33: ='EP10'!N42 | I33: =H33+G33+F33+E33+D33+C33 | J33: =I33*B33
A34: RC258 | B34: 1 | I34: =H34+G34+F34+E34+D34+C34 | J34: =I34*B34
A35: RC259 | B35: 1.5 | I35: =H35+G35+F35+E35+D35+C35 | J35: =I35*B35
A36: RC260 | B36: Total | C36: =C30+C31+C32+C33+C34+C35 | D36: =D30+D31+D32+D33+D34+D35 | E36: =E30+E31+E32+E33+E34+E35 | F36: =F30+F31+F32+F33+F34+F35 | G36: =G30+G31+G32+G33+G34+G35 | H36: =H30+H31+H32+H33+H34+H35 | I36: =I30+I31+I32+I33+I34+I35 | J36: =J30+J31+J32+J33+J34+J35
A38: RC261 | B38: TOTAL EXPOSITIONS SUR LES PG/IC | C38: =C18+C27+C36 | D38: =D18+D27+D36 | E38: =E18+E27+E36 | F38: =F18+F27+F36 | G38: =G18+G27+G36 | H38: =H18+H27+H36 | I38: =I18+I27+I36 | J38: =J18+J27+J36

Sheet EP20
A1: RISQUE DE CREDIT : EXPOSITIONS SUR LES AUTRES ACTIFS | E1: EP 20
A8: Code DISPRU | B8: Poste | C8: Exposition nette | D8: Coefficient de pondération | E8: Actifs pondérés des risques
C9: (a) | D9: (b) | E9: (c )= a x b
A10: RC262 | B10: Caisse | D10: 0 | E10: =C10*D10
A11: RC263 | B11: Lingot d'or | D11: 0 | E11: =C11*D11
A12: RC264 | B12: Valeurs à l'encaissement avec crédit immédiat, chèques et autres effets en transit (liquidité en cours de recouvrement) | D12: 0.2 | E12: =C12*D12
A13: PA166 | B13: Participations non significatives non déduites des fonds propres | D13: 1 | E13: =C13*D13
A14: RC265 | B14: Immobilisations corporelles nettes d'amortissement | D14: 1 | E14: =C14*D14
A15: RC266 | B15: Comptes d'ordre et divers | C15: =-2960+31 | D15: 1 | E15: =C15*D15
A16: RC267 | B16: Dépôts et cautionnements | D16: 1 | E16: =C16*D16
A17: RC268 | B17: Débiteurs divers | D17: 1 | E17: =C17*D17
A18: RC269 | B18: Part dans les fonds communs de placement | D18: 1 | E18: =C18*D18
A19: RC270 | B19: Comptes de stock | D19: 1 | E19: =C19*D19
A20: RC271 | B20: Actions | D20: 1 | E20: =C20*D20
A21: RC272 | B21: Expositions des entreprises à caractère financier hors UMOA incluses dans le périmètre de consolidation prudentielle | D21: 1 | E21: =C21*D21
A22: RC273 | B22: Expositions sur des entreprises soumises à une procédure de traitement prudentiel | D22: 1.5 | E22: =C22*D22
A23: PA176 | B23: Participations significatives non déduites des fonds propres | D23: 2.5 | E23: =C23*D23
A24: ID012 | B24: Impôts différés actifs découlant de différences temporaires non déduites des fonds propres | D24: 2.5 | E24: =C24*D24
A25: RC274 | B25: Expositions sur les établissements qui ne respectent pas les ratios de solvabilité | D25: 2.5 | E25: =C25*D25
A26: RC275 | B26: Autres éléments d'actif non pris en compte | C26: =-22157+19802 | D26: 1 | E26: =C26*D26
A27: RC276 | B27: TOTAL EXPOSITIONS SUR LES AUTRES ACTIFS | C27: =C10+C11+C12+C13+C14+C15+C16+C17+C18+C19+C20+C21+C22+C23+C24+C25+C26 | E27: =E10+E11+E12+E13+E14+E15+E16+E17+E18+E19+E20+E21+E22+E23+E24+E25+E26

Sheet EP21
A1: RISQUE OPERATIONNEL : EXIGENCES DE FONDS PROPRES AU TITRE DE L'APPROCHE INDICATEUR DE BASE | H1: EP21
A8: A. Calcul du produit brut
A10: Code DISPRU | B10: Poste | D10: Montant
A11: RO001 | B11: Produit d'exploitation bancaire
A12: RO002 | B12: Moins-values réalisées sur cessions de titres du portefeuille bancaire
A13: RO003 | B13: (-) Charges d'exploitation bancaire
